[2023-03-30 20:29:55,418] - logger_.py] - ERROR: 请求错误:HTTPSConnectionPool(host='app.hinance.onlinehttps', port=443): Max retries exceeded with url: //app.hinance.online/hc/app/noAuth/logon/login (Caused by SSLError(SSLEOFError(8, 'EOF occurred in violation of protocol (_ssl.c:997)')))
[2023-03-30 20:30:02,607] - logger_.py] - ERROR: 请求错误:HTTPSConnectionPool(host='app.hinance.onlinehttps', port=443): Max retries exceeded with url: //app.hinance.online/hc/app/noAuth/logon/login (Caused by NewConnectionError('<urllib3.connection.HTTPSConnection object at 0x0000025E6DED9390>: Failed to establish a new connection: [Errno 11001] getaddrinfo failed'))
[2023-03-30 20:30:22,084] - logger_.py] - ERROR: 请求错误:HTTPSConnectionPool(host='app.hinance.onlinehttps', port=443): Max retries exceeded with url: //app.hinance.online/hc/app/noAuth/logon/login (Caused by NewConnectionError('<urllib3.connection.HTTPSConnection object at 0x0000026356F59390>: Failed to establish a new connection: [Errno 11001] getaddrinfo failed'))
[2023-03-30 20:32:19,745] - logger_.py] - ERROR: 请求错误:HTTPSConnectionPool(host='app.hinance.onlinehttps', port=443): Max retries exceeded with url: //app.hinance.online/hc/app/noAuth/logon/login (Caused by NewConnectionError('<urllib3.connection.HTTPSConnection object at 0x0000024A94F49390>: Failed to establish a new connection: [Errno 11001] getaddrinfo failed'))
